Workbook

Sheet Summary
A1: 0580-Security Technology Salutation after eliminating Passenger Checking Roles | Rev 1: baseline schedule, cost loading and BOQ mapping
A3: Project number and name | B3: 0580-Security Technology Salutation after eliminating Passenger Checking Roles
A4: Source of cost | B4: Signed contract with ETECHS (1 November 2026): Annex 3 price table (Revised-02) and clause 15 payment milestones
A5: Contract price | B5: 62000000
A6: Project start (NTP milestone) | B6: 46327
A7: Contract term end (36 months) | B7: 47422
A8: Activities | B8: 591
A9: Tasks (2 resources each) | B9: 500
A10: Milestones | B10: 91
A11: Cost loaded in P6 (SAR) | B11: =BOQ_Mapping!N505
A12: Difference to contract price | B12: =B11-B5
A13: Progress points loaded | B13: =BOQ_Mapping!R505
A14: Working calendar | B14: Sunday to Thursday, 8 hours; KSA official holidays; Eid dates are estimates to be updated
A15: How to read | B15: Station_BOQ gives the BOQ value of each station; Payment_Milestones applies the contract payment conditions; BOQ_Mapping shows each activity cost; Distribution_Keys explains the keys; S_Curve shows cost against progress; Invoicing_Monthly lists every invoice by month, milestone and station.

Sheet Station_BOQ
A1: Annex 3 price table: BOQ value by station (SAR, excluding VAT)
A2: A1-A6 are priced per station. Shared packages (design, PM, FAT, spares, training, cloud) are priced per railway and allocated to stations pro rata to A1-A6 hardware value.
A4: Station | B4: Railway | C4: A1 CCTV | D4: A2 Video mgmt and wall | E4: A3 Access and intercom | F4: A4 UPS | G4: A5 Poles, cabinets, network | H4: A6 Civil works | I4: Hardware subtotal | J4: Design and engineering | K4: Project management | L4: FAT | M4: Commissioning spares | N4: Training | O4: Cloud (12 mo) | P4: Shared total | Q4: Station value | R4: Share of price
A5: Riyadh (Thumamah) (NRY) | B5: NSR | C5: 338989 | D5: 417141 | E5: 44085 | F5: 56211 | G5: 860619 | H5: 745743 | I5: =SUM(C5:H5) | J5: 82837.4 | K5: 744951.98 | L5: 34510.376 | M5: 66982.13 | N5: 6573.9871 | O5: 82141.898 | P5: =SUM(J5:O5) | Q5: =I5+P5 | R5: =Q5/Q$19
A6: Makkah (HMK) | B6: HHR | C6: 1650175 | D6: 552237 | E6: 44085 | F6: 110563 | G6: 2715976 | H6: 571639 | I6: =SUM(C6:H6) | J6: 337786.51 | K6: 3026065.7 | L6: 64944.147 | M6: 175360.16 | N6: 21649.327 | O6: 439615.13 | P6: =SUM(J6:O6) | Q6: =I6+P6 | R6: =Q6/Q$19
A7: Riyadh (Malaz) (ERY) | B7: EWR | C7: 276849 | D7: 350866 | E7: 44085 | F7: 50114 | G7: 548042 | H7: 701825 | I7: =SUM(C7:H7) | J7: 86494.688 | K7: 779124.28 | L7: 56538.427 | M7: 106509.2 | N7: 18847.255 | O7: 72225.509 | P7: =SUM(J7:O7) | Q7: =I7+P7 | R7: =Q7/Q$19
A8: Jeddah (HJD) | B8: HHR | C8: 1391206 | D8: 652091 | E8: 44085 | F8: 102666 | G8: 2840354 | H8: 521718 | I8: =SUM(C8:H8) | J8: 332247.87 | K8: 2976447.7 | L8: 63879.266 | M8: 172484.8 | N8: 21294.346 | O8: 432406.82 | P8: =SUM(J8:O8) | Q8: =I8+P8 | R8: =Q8/Q$19
A9: Dammam (EDM) | B9: EWR | C9: 276849 | D9: 412102 | E9: 44085 | F9: 50114 | G9: 548042 | H9: 701813 | I9: =SUM(C9:H9) | J9: 89180.357 | K9: 803316.17 | L9: 58293.95 | M9: 109816.32 | N9: 19432.464 | O9: 74468.119 | P9: =SUM(J9:O9) | Q9: =I9+P9 | R9: =Q9/Q$19
A10: Al Qassim (NQS) | B10: NSR | C10: 338989 | D10: 359215 | E10: 44085 | F10: 56211 | G10: 860619 | H10: 745743 | I10: =SUM(C10:H10) | J10: 80889.023 | K10: 727430.34 | L10: 33698.675 | M10: 65406.677 | N10: 6419.3637 | O10: 80209.88 | P10: =SUM(J10:O10) | Q10: =I10+P10 | R10: =Q10/Q$19
A11: Hufuf (EHF) | B11: EWR | C11: 192155 | D11: 349033 | E11: 44085 | F11: 50114 | G11: 508774 | H11: 659866 | I11: =SUM(C11:H11) | J11: 79135.945 | K11: 712838.41 | L11: 51728.284 | M11: 97447.677 | N11: 17243.779 | O11: 66080.751 | P11: =SUM(J11:O11) | Q11: =I11+P11 | R11: =Q11/Q$19
A12: Al Majma'ah (NMJ) | B12: NSR | C12: 338989 | D12: 359215 | E12: 44085 | F12: 56211 | G12: 860619 | H12: 745743 | I12: =SUM(C12:H12) | J12: 80889.023 | K12: 727430.34 | L12: 33698.675 | M12: 65406.677 | N12: 6419.3637 | O12: 80209.88 | P12: =SUM(J12:O12) | Q12: =I12+P12 | R12: =Q12/Q$19
A13: KAEC (HKA) | B13: HHR | C13: 962039 | D13: 406364 | E13: 44085 | F13: 82168 | G13: 1552977 | H13: 187054 | I13: =SUM(C13:H13) | J13: 193568.92 | K13: 1734090.2 | L13: 37216.312 | M13: 100490.32 | N13: 12406.17 | O13: 251921.92 | P13: =SUM(J13:O13) | Q13: =I13+P13 | R13: =Q13/Q$19
A14: Madinah (HMD) | B14: HHR | C14: 934319 | D14: 409184 | E14: 44085 | F14: 74329 | G14: 1480427 | H14: 291036 | I14: =SUM(C14:H14) | J14: 193490.7 | K14: 1733389.5 | L14: 37201.275 | M14: 100449.72 | N14: 12401.157 | O14: 251820.13 | P14: =SUM(J14:O14) | Q14: =I14+P14 | R14: =Q14/Q$19
A15: Abqaiq (EAB) | B15: EWR | C15: 111083 | D15: 286032 | E15: 44085 | F15: 50114 | G15: 411979 | H15: 375936 | I15: =SUM(C15:H15) | J15: 56115.011 | K15: 505471.13 | L15: 36680.339 | M15: 69099.794 | N15: 12227.501 | O15: 46857.621 | P15: =SUM(J15:O15) | Q15: =I15+P15 | R15: =Q15/Q$19
A16: Hail (NHL) | B16: NSR | C16: 338989 | D16: 359215 | E16: 44085 | F16: 56211 | G16: 860619 | H16: 745743 | I16: =SUM(C16:H16) | J16: 80889.023 | K16: 727430.34 | L16: 33698.675 | M16: 65406.677 | N16: 6419.3637 | O16: 80209.88 | P16: =SUM(J16:O16) | Q16: =I16+P16 | R16: =Q16/Q$19
... A18: Al Qurayyat (NQR) | B18: NSR | C18: 338989 | D18: 359215 | E18: 44085 | F18: 56211 | G18: 860619 | H18: 745743 | I18: =SUM(C18:H18) | J18: 80889.023 | K18: 727430.34 | L18: 33698.675 | M18: 65406.677 | N18: 6419.3637 | O18: 80209.88 | P18: =SUM(J18:O18) | Q18: =I18+P18 | R18: =Q18/Q$19
A19: Total | C19: =SUM(C5:C18) | D19: =SUM(D5:D18) | E19: =SUM(E5:E18) | F19: =SUM(F5:F18) | G19: =SUM(G5:G18) | H19: =SUM(H5:H18) | I19: =SUM(I5:I18) | J19: =SUM(J5:J18) | ... R19: =SUM(R5:R18)
A21: Contract price (Annex 3) | C21: 62000000
A22: Difference (should be zero within SAR 5) | C22: =Q19-C21

Sheet Payment_Milestones
A1: Contract clause 15 payment milestones applied to each station price
A2: MS1 Mobilization is 20% of the TOTAL price. MS2 to MS7 are prorated per station on the station share of the price.
A4: Milestone | B4: Description | C4: Share of price | D4: Amount (SAR)
A5: MS1 | B5: Mobilization | C5: 0.2 | D5: =C5*62000000
A6: MS2 | B6: Engineering submittal | C6: 0.1 | D6: =C6*62000000
A7: MS3 | B7: SAR approval of engineering | C7: 0.1 | D7: =C7*62000000
A8: MS4 | B8: Material delivery | C8: 0.2 | D8: =C8*62000000
A9: MS5 | B9: Installation | C9: 0.2 | D9: =C9*62000000
A10: MS6 | B10: Testing and commissioning (SAT) | C10: 0.1 | D10: =C10*62000000
A11: MS7 | B11: Final acceptance and handover | C11: 0.1 | D11: =C11*62000000
A12: Total | C12: =SUM(C5:C11) | D12: =SUM(D5:D11)
A15: Station | B15: Station share | C15: MS2 amount | D15: MS3 amount | E15: MS4 amount | F15: MS5 amount | G15: MS6 amount | H15: MS7 amount | I15: Stations total MS2-MS7
A16: Riyadh (Thumamah) (NRY) | B16: =Station_BOQ!R5 | C16: =$B16*62000000*$C$6 | D16: =$B16*62000000*$C$7 | E16: =$B16*62000000*$C$8 | F16: =$B16*62000000*$C$9 | G16: =$B16*62000000*$C$10 | H16: =$B16*62000000*$C$11 | I16: =SUM(C16:H16)
A17: Makkah (HMK) | B17: =Station_BOQ!R6 | C17: =$B17*62000000*$C$6 | D17: =$B17*62000000*$C$7 | E17: =$B17*62000000*$C$8 | F17: =$B17*62000000*$C$9 | G17: =$B17*62000000*$C$10 | H17: =$B17*62000000*$C$11 | I17: =SUM(C17:H17)
A18: Riyadh (Malaz) (ERY) | B18: =Station_BOQ!R7 | C18: =$B18*62000000*$C$6 | D18: =$B18*62000000*$C$7 | E18: =$B18*62000000*$C$8 | F18: =$B18*62000000*$C$9 | G18: =$B18*62000000*$C$10 | H18: =$B18*62000000*$C$11 | I18: =SUM(C18:H18)
A19: Jeddah (HJD) | B19: =Station_BOQ!R8 | C19: =$B19*62000000*$C$6 | D19: =$B19*62000000*$C$7 | E19: =$B19*62000000*$C$8 | F19: =$B19*62000000*$C$9 | G19: =$B19*62000000*$C$10 | H19: =$B19*62000000*$C$11 | I19: =SUM(C19:H19)
A20: Dammam (EDM) | B20: =Station_BOQ!R9 | C20: =$B20*62000000*$C$6 | D20: =$B20*62000000*$C$7 | E20: =$B20*62000000*$C$8 | F20: =$B20*62000000*$C$9 | G20: =$B20*62000000*$C$10 | H20: =$B20*62000000*$C$11 | I20: =SUM(C20:H20)
A21: Al Qassim (NQS) | B21: =Station_BOQ!R10 | C21: =$B21*62000000*$C$6 | D21: =$B21*62000000*$C$7 | E21: =$B21*62000000*$C$8 | F21: =$B21*62000000*$C$9 | G21: =$B21*62000000*$C$10 | H21: =$B21*62000000*$C$11 | I21: =SUM(C21:H21)
A22: Hufuf (EHF) | B22: =Station_BOQ!R11 | C22: =$B22*62000000*$C$6 | D22: =$B22*62000000*$C$7 | E22: =$B22*62000000*$C$8 | F22: =$B22*62000000*$C$9 | G22: =$B22*62000000*$C$10 | H22: =$B22*62000000*$C$11 | I22: =SUM(C22:H22)
A23: Al Majma'ah (NMJ) | B23: =Station_BOQ!R12 | C23: =$B23*62000000*$C$6 | D23: =$B23*62000000*$C$7 | E23: =$B23*62000000*$C$8 | F23: =$B23*62000000*$C$9 | G23: =$B23*62000000*$C$10 | H23: =$B23*62000000*$C$11 | I23: =SUM(C23:H23)
A24: KAEC (HKA) | B24: =Station_BOQ!R13 | C24: =$B24*62000000*$C$6 | D24: =$B24*62000000*$C$7 | E24: =$B24*62000000*$C$8 | F24: =$B24*62000000*$C$9 | G24: =$B24*62000000*$C$10 | H24: =$B24*62000000*$C$11 | I24: =SUM(C24:H24)
A25: Madinah (HMD) | B25: =Station_BOQ!R14 | C25: =$B25*62000000*$C$6 | D25: =$B25*62000000*$C$7 | E25: =$B25*62000000*$C$8 | F25: =$B25*62000000*$C$9 | G25: =$B25*62000000*$C$10 | H25: =$B25*62000000*$C$11 | I25: =SUM(C25:H25)
A26: Abqaiq (EAB) | B26: =Station_BOQ!R15 | C26: =$B26*62000000*$C$6 | D26: =$B26*62000000*$C$7 | E26: =$B26*62000000*$C$8 | F26: =$B26*62000000*$C$9 | G26: =$B26*62000000*$C$10 | H26: =$B26*62000000*$C$11 | I26: =SUM(C26:H26)
A27: Hail (NHL) | B27: =Station_BOQ!R16 | C27: =$B27*62000000*$C$6 | D27: =$B27*62000000*$C$7 | E27: =$B27*62000000*$C$8 | F27: =$B27*62000000*$C$9 | G27: =$B27*62000000*$C$10 | H27: =$B27*62000000*$C$11 | I27: =SUM(C27:H27)
... A29: Al Qurayyat (NQR) | B29: =Station_BOQ!R18 | C29: =$B29*62000000*$C$6 | D29: =$B29*62000000*$C$7 | E29: =$B29*62000000*$C$8 | F29: =$B29*62000000*$C$9 | G29: =$B29*62000000*$C$10 | H29: =$B29*62000000*$C$11 | I29: =SUM(C29:H29)
A30: Total | B30: =SUM(B16:B29) | C30: =SUM(C16:C29) | D30: =SUM(D16:D29) | E30: =SUM(E16:E29) | F30: =SUM(F16:F29) | G30: =SUM(G16:G29) | H30: =SUM(H16:H29) | I30: =SUM(I16:I29)
A32: Check: MS1 + stations MS2-MS7 = total price | D32: =D5+I30

Sheet BOQ_Mapping
A1: Activity cost mapping: how each activity cost was distributed from the BOQ
A2: BOQ ID uses the Annex 3 section codes A1 to A6; the shared per-railway packages carry derived IDs SH-xx. Cost = milestone amount (payment condition x station share of the BOQ) x distribution key. Column M recomputes it with formulas; column N is the whole-riyal value loaded in P6.
A4: BOQ ID | B4: BOQ Description | C4: Activity ID | D4: Activity name | E4: WBS | F4: EPC phase | G4: Station | H4: Payment milestone | I4: Milestone % | J4: Station price share | K4: Milestone amount (SAR) | L4: Distribution key | M4: Cost recomputed | N4: Cost in P6 (SAR) | O4: Difference | P4: Distribution basis | Q4: Primary BOQ source | R4: Progress points | S4: Progress % of project | T4: Start | U4: Finish | V4: Duration (work days)
A5: TOTAL | B5: Contract price (Annex 3 total, SAR 62,000,000): 20% mobilization payment, clause 15 | C5: PRJ-A1010 | D5: Performance security, insurance and key personnel approval | E5: PM.MOB | F5: Mobilization | G5: PRJ | H5: MS1 | I5: 0.2 | K5: =Payment_Milestones!D5 | L5: 0.15 | M5: =ROUND(K5*L5,0) | N5: 1859999 | O5: =N5-M5 | P5: MS1 Mobilization 20% of the total price (SAR 12,400,000) x key 15% | Q5: Contract price (62,000,000) x 20% mobilization payment (contract clause 15) | R5: 400 | S5: =R5/1000 | T5: 46327 | U5: 46338 | V5: 10
A6: TOTAL | B6: Contract price (Annex 3 total, SAR 62,000,000): 20% mobilization payment, clause 15 | C6: PRJ-A1020 | D6: Initial baseline programme (Primavera) covering mobilization and survey | E6: PM.MOB | F6: Mobilization | G6: PRJ | H6: MS1 | I6: 0.2 | K6: =Payment_Milestones!D5 | L6: 0.1 | M6: =ROUND(K6*L6,0) | N6: 1239999 | O6: =N6-M6 | P6: MS1 Mobilization 20% of the total price (SAR 12,400,000) x key 10% | Q6: Contract price (62,000,000) x 20% mobilization payment (contract clause 15) | R6: 200 | S6: =R6/1000 | T6: 46327 | U6: 46335 | V6: 7
A7: - | B7: No BOQ cost: administrative or review step with no payment milestone | C7: PRJ-A1030 | D7: SAR review and approval of initial baseline | E7: PM.MOB | F7: Mobilization | G7: PRJ | I7: 0 | K7: 0 | L7: 0 | M7: 0 | N7: 0 | O7: =N7-M7 | P7: No payment milestone attached (administrative approval or review step) | Q7: - | R7: 200 | S7: =R7/1000 | T7: 46336 | U7: 46356 | V7: 15
A8: TOTAL | B8: Contract price (Annex 3 total, SAR 62,000,000): 20% mobilization payment, clause 15 | C8: PRJ-A1040 | D8: Mobilization: site establishment, offices, personnel and tools | E8: PM.MOB | F8: Mobilization | G8: PRJ | H8: MS1 | I8: 0.2 | K8: =Payment_Milestones!D5 | L8: 0.45 | M8: =ROUND(K8*L8,0) | N8: 5579999 | O8: =N8-M8 | P8: MS1 Mobilization 20% of the total price (SAR 12,400,000) x key 45% | Q8: Contract price (62,000,000) x 20% mobilization payment (contract clause 15) | R8: 700 | S8: =R8/1000 | T8: 46334 | U8: 46366 | V8: 25
A9: TOTAL | B9: Contract price (Annex 3 total, SAR 62,000,000): 20% mobilization payment, clause 15 | C9: PRJ-A1050 | D9: Mobilization submittals: QC programme and ITP, HSE, security, procurement and shipping plan | E9: PM.MOB | F9: Mobilization | G9: PRJ | H9: MS1 | I9: 0.2 | K9: =Payment_Milestones!D5 | L9: 0.3 | M9: =ROUND(K9*L9,0) | N9: 3719999 | O9: =N9-M9 | P9: MS1 Mobilization 20% of the total price (SAR 12,400,000) x key 30% | Q9: Contract price (62,000,000) x 20% mobilization payment (contract clause 15) | R9: 600 | S9: =R9/1000 | T9: 46334 | U9: 46359 | V9: 20
A10: - | B10: No BOQ cost: administrative or review step with no payment milestone | C10: PRJ-A1060 | D10: Site access permits for the surveys of all stations: application and approval (two months) | E10: PM.MOB | F10: Mobilization | G10: PRJ | I10: 0 | K10: 0 | L10: 0 | M10: 0 | N10: 0 | O10: =N10-M10 | P10: No payment milestone attached (administrative approval or review step) | Q10: - | R10: 100 | S10: =R10/1000 | T10: 46327 | U10: 46387 | V10: 45
A11: - | B11: No BOQ cost: administrative or review step with no payment milestone | C11: PRJ-A2010 | D11: Detailed baseline programme (after mobilization) | E11: PM.MOB | F11: Project management | G11: PRJ | I11: 0 | K11: 0 | L11: 0 | M11: 0 | N11: 0 | O11: =N11-M11 | P11: No payment milestone attached (administrative approval or review step) | Q11: - | R11: 300 | S11: =R11/1000 | T11: 46390 | U11: 46408 | V11: 15
A12: - | B12: No BOQ cost: administrative or review step with no payment milestone | C12: PRJ-A2020 | D12: SAR review and approval of detailed baseline | E12: PM.MOB | F12: Project management | G12: PRJ | I12: 0 | K12: 0 | L12: 0 | M12: 0 | N12: 0 | O12: =N12-M12 | P12: No payment milestone attached (administrative approval or review step) | Q12: - | R12: 200 | S12: =R12/1000 | T12: 46411 | U12: 46429 | V12: 15
A13: - | B13: No BOQ cost: administrative or review step with no payment milestone | C13: PRJ-C1010 | D13: Contract closeout pack and handover documentation | E13: PM.CLO | F13: Project management | G13: PRJ | I13: 0 | K13: 0 | L13: 0 | M13: 0 | N13: 0 | O13: =N13-M13 | P13: No payment milestone attached (administrative approval or review step) | Q13: - | R13: 1301 | S13: =R13/1000 | T13: 47374 | U13: 47388 | V13: 10
A14: SH-DES | B14: Design and engineering package (per railway, allocated to the station) | C14: NRY-E1010 | D14: Survey: submittal of site survey and as-found report - Riyadh (Thumamah) | E14: ENG.NRY.SRV.SUB | F14: Engineering | G14: NRY | H14: MS2 | I14: 0.1 | J14: =Station_BOQ!R5 | K14: =I14*62000000*J14 | L14: 0.069 | M14: =ROUND(K14*L14,0) | N14: 24017 | O14: =N14-M14 | P14: MS2 Engineering submittal 10% x station price share 5.61% | Design stage key 6.9% of the engineering-submittal milestone | Q14: Annex 3 Design and engineering package (railway) allocated by station hardware share | R14: 31 | S14: =R14/1000 | T14: 46390 | U14: 46399 | V14: 8
A15: SH-DES | B15: Design and engineering package (per railway, allocated to the station) | C15: NRY-E1020 | D15: Survey: SAR approval of survey report - Riyadh (Thumamah) | E15: ENG.NRY.SRV.APR | F15: Engineering | G15: NRY | H15: MS3 | I15: 0.1 | J15: =Station_BOQ!R5 | K15: =I15*62000000*J15 | L15: 0.05 | M15: =ROUND(K15*L15,0) | N15: 17404 | O15: =N15-M15 | P15: MS3 SAR approval of engineering 10% x station price share 5.61% | Design stage key 5.0% of the SAR-approval milestone | Q15: Annex 3 Design and engineering package (railway) allocated by station hardware share | R15: 33 | S15: =R15/1000 | T15: 46400 | U15: 46420 | V15: 15
A16: SH-DES | B16: Design and engineering package (per railway, allocated to the station) | C16: NRY-E1030 | D16: Concept design: submittal - Riyadh (Thumamah) | E16: ENG.NRY.CNC.SUB | F16: Engineering | G16: NRY | H16: MS2 | I16: 0.1 | J16: =Station_BOQ!R5 | K16: =I16*62000000*J16 | L16: 0.098 | M16: =ROUND(K16*L16,0) | N16: 34112 | O16: =N16-M16 | P16: MS2 Engineering submittal 10% x station price share 5.61% | Design stage key 9.8% of the engineering-submittal milestone | Q16: Annex 3 Design and engineering package (railway) allocated by station hardware share | R16: 22 | S16: =R16/1000 | T16: 46400 | U16: 46411 | V16: 8
A17: SH-DES | B17: Design and engineering package (per railway, allocated to the station) | C17: NRY-E1040 | D17: Concept design: SAR review and approval - Riyadh (Thumamah) | E17: ENG.NRY.CNC.APR | F17: Engineering | G17: NRY | H17: MS3 | I17: 0.1 | J17: =Station_BOQ!R5 | K17: =I17*62000000*J17 | L17: 0.1 | M17: =ROUND(K17*L17,0) | N17: 34808 | O17: =N17-M17 | P17: MS3 SAR approval of engineering 10% x station price share 5.61% | Design stage key 10.0% of the SAR-approval milestone | Q17: Annex 3 Design and engineering package (railway) allocated by station hardware share | R17: 41 | S17: =R17/1000 | T17: 46412 | U17: 46432 | V17: 15
A18: SH-DES | B18: Design and engineering package (per railway, allocated to the station) | C18: NRY-E1050 | D18: Preliminary design: submittal - Riyadh (Thumamah) | E18: ENG.NRY.PRE.SUB | F18: Engineering | G18: NRY | H18: MS2 | I18: 0.1 | J18: =Station_BOQ!R5 | K18: =I18*62000000*J18 | L18: 0.196 | M18: =ROUND(K18*L18,0) | N18: 68223 | O18: =N18-M18 | P18: MS2 Engineering submittal 10% x station price share 5.61% | Design stage key 19.6% of the engineering-submittal milestone | Q18: Annex 3 Design and engineering package (railway) allocated by station hardware share | R18: 55 | S18: =R18/1000 | T18: 46412 | U18: 46429 | V18: 14
A19: SH-DES | B19: Design and engineering package (per railway, allocated to the station) | C19: NRY-E1060 | D19: Preliminary design: SAR review and approval - Riyadh (Thumamah) | E19: ENG.NRY.PRE.APR | F19: Engineering | G19: NRY | H19: MS3 | I19: 0.1 | J19: =Station_BOQ!R5 | K19: =I19*62000000*J19 | L19: 0.2 | M19: =ROUND(K19*L19,0) | N19: 69616 | O19: =N19-M19 | P19: MS3 SAR approval of engineering 10% x station price share 5.61% | Design stage key 20.0% of the SAR-approval milestone | Q19: Annex 3 Design and engineering package (railway) allocated by station hardware share | R19: 59 | S19: =R19/1000 | T19: 46432 | U19: 46460 | V19: 15
A20: SH-DES | B20: Design and engineering package (per railway, allocated to the station) | C20: NRY-E1070 | D20: Detailed design: submittal (drawings, BOQ, data sheets) - Riyadh (Thumamah) | E20: ENG.NRY.DET.SUB | F20: Engineering | G20: NRY | H20: MS2 | I20: 0.1 | J20: =Station_BOQ!R5 | K20: =I20*62000000*J20 | L20: 0.392 | M20: =ROUND(K20*L20,0) | N20: 136447 | O20: =N20-M20 | P20: MS2 Engineering submittal 10% x station price share 5.61% | Design stage key 39.2% of the engineering-submittal milestone | Q20: Annex 3 Design and engineering package (railway) allocated by station hardware share | R20: 113 | S20: =R20/1000 | T20: 46432 | U20: 46469 | V20: 22
A21: SH-DES | B21: Design and engineering package (per railway, allocated to the station) | C21: NRY-E1080 | D21: Detailed design: SAR review and approval - Riyadh (Thumamah) | E21: ENG.NRY.DET.APR | F21: Engineering | G21: NRY | H21: MS3 | I21: 0.1 | J21: =Station_BOQ!R5 | K21: =I21*62000000*J21 | L21: 0.4 | M21: =ROUND(K21*L21,0) | N21: 139231 | O21: =N21-M21 | P21: MS3 SAR approval of engineering 10% x station price share 5.61% | Design stage key 40.0% of the SAR-approval milestone | Q21: Annex 3 Design and engineering package (railway) allocated by station hardware share | R21: 77 | S21: =R21/1000 | T21: 46470 | U21: 46490 | V21: 15
A22: SH-DES | B22: Design and engineering package (per railway, allocated to the station) | C22: NRY-E1090 | D22: IFC and shop drawings: submittal - Riyadh (Thumamah) | E22: ENG.NRY.IFC.SUB | F22: Engineering | G22: NRY | H22: MS2 | I22: 0.1 | J22: =Station_BOQ!R5 | K22: =I22*62000000*J22 | L22: 0.196 | M22: =ROUND(K22*L22,0) | N22: 68223 | O22: =N22-M22 | P22: MS2 Engineering submittal 10% x station price share 5.61% | Design stage key 19.6% of the engineering-submittal milestone | Q22: Annex 3 Design and engineering package (railway) allocated by station hardware share | R22: 51 | S22: =R22/1000 | T22: 46470 | U22: 46485 | V22: 12
A23: SH-DES | B23: Design and engineering package (per railway, allocated to the station) | C23: NRY-E1100 | D23: IFC and shop drawings: SAR approval and release - Riyadh (Thumamah) | E23: ENG.NRY.IFC.APR | F23: Engineering | G23: NRY | H23: MS3 | I23: 0.1 | J23: =Station_BOQ!R5 | K23: =I23*62000000*J23 | L23: 0.2 | M23: =ROUND(K23*L23,0) | N23: 69616 | O23: =N23-M23 | P23: MS3 SAR approval of engineering 10% x station price share 5.61% | Design stage key 20.0% of the SAR-approval milestone | Q23: Annex 3 Design and engineering package (railway) allocated by station hardware share | R23: 63 | S23: =R23/1000 | T23: 46488 | U23: 46506 | V23: 15
A24: SH-DES | B24: Design and engineering package (per railway, allocated to the station) | C24: NRY-E1110 | D24: HCIS Stage 3 and 4 documents: preparation - Riyadh (Thumamah) | E24: ENG.NRY.HCS.SUB | F24: Engineering | G24: NRY | H24: MS2 | I24: 0.1 | J24: =Station_BOQ!R5 | K24: =I24*62000000*J24 | L24: 0.049 | M24: =ROUND(K24*L24,0) | N24: 17056 | O24: =N24-M24 | P24: MS2 Engineering submittal 10% x station price share 5.61% | Design stage key 4.9% of the engineering-submittal milestone | Q24: Annex 3 Design and engineering package (railway) allocated by station hardware share | R24: 24 | S24: =R24/1000 | T24: 46443 | U24: 46485 | V24: 26
A25: SH-DES | B25: Design and engineering package (per railway, allocated to the station) | C25: NRY-E1120 | D25: HCIS Stage 3 and 4 documents: SAR final review and HCIS submission - Riyadh (Thumamah) | E25: ENG.NRY.HCS.APR | F25: Engineering | G25: NRY | H25: MS3 | I25: 0.1 | J25: =Station_BOQ!R5 | K25: =I25*62000000*J25 | L25: 0.05 | M25: =ROUND(K25*L25,0) | N25: 17404 | O25: =N25-M25 | P25: MS3 SAR approval of engineering 10% x station price share 5.61% | Design stage key 5.0% of the SAR-approval milestone | Q25: Annex 3 Design and engineering package (railway) allocated by station hardware share | R25: 14 | S25: =R25/1000 | T25: 46488 | U25: 46506 | V25: 15
A26: SH-DES, SH-TRN | B26: Design and engineering package (per railway, allocated to the station) and Training (per railway, allocated): documentation and training share | C26: NRY-E1130 | D26: As-built and O&M documentation: submittal - Riyadh (Thumamah) | E26: ENG.NRY.ASB.SUB | F26: Engineering | G26: NRY | H26: MS7 | I26: 0.1 | J26: =Station_BOQ!R5 | K26: =I26*62000000*J26 | L26: 0.15 | M26: =ROUND(K26*L26,0) | N26: 52212 | O26: =N26-M26 | P26: MS7 Final acceptance and handover 10% x station price share 5.61% | Fixed key 15% of final-acceptance milestone | Q26: Annex 3 documentation and training share | R26: 41 | S26: =R26/1000 | T26: 46695 | U26: 46734 | V26: 28
A27: SH-DES | B27: Design and engineering package (per railway, allocated to the station): documentation share | C27: NRY-E1140 | D27: As-built and O&M documentation: SAR review and approval - Riyadh (Thumamah) | E27: ENG.NRY.ASB.APR | F27: Engineering | G27: NRY | H27: MS7 | I27: 0.1 | J27: =Station_BOQ!R5 | K27: =I27*62000000*J27 | L27: 0.05 | M27: =ROUND(K27*L27,0) | N27: 17404 | O27: =N27-M27 | P27: MS7 Final acceptance and handover 10% x station price share 5.61% | Fixed key 5% | Q27: Annex 3 documentation share | R27: 22 | S27: =R27/1000 | T27: 46735 | U27: 46755 | V27: 15
A28: - | B28: No BOQ cost: administrative or review step with no payment milestone | C28: NRY-X1010 | D28: Enabling works: site preparation, setting out, temporary works and utilities clearance - Riyadh (Thumamah) | E28: CON.NRY.ENA | F28: Construction | G28: NRY | H28: MS5 | I28: 0.2 | J28: =Station_BOQ!R5 | K28: =I28*62000000*J28 | L28: 0.012112175 | M28: =ROUND(K28*L28,0) | N28: 8432 | O28: =N28-M28 | P28: MS5 Installation 20% x station price share 5.61% | BOQ civil share 30.3% x 4% (enabling: site preparation) | Q28: Annex 3 A6 Civil works (SAR 745,743) | R28: 54 | S28: =R28/1000 | T28: 46509 | U28: 46520 | V28: 10
A29: - | B29: No BOQ cost: administrative or review step with no payment milestone | C29: NRY-X1020 | D29: Enabling works: cable routes, duct-bank and cabinet plinth preparation - Riyadh (Thumamah) | E29: CON.NRY.ENA | F29: Construction | G29: NRY | H29: MS5 | I29: 0.2 | J29: =Station_BOQ!R5 | K29: =I29*62000000*J29 | L29: 0.018168263 | M29: =ROUND(K29*L29,0) | N29: 12648 | O29: =N29-M29 | P29: MS5 Installation 20% x station price share 5.61% | BOQ civil share 30.3% x 6% (enabling: routes, ducts, plinths) | Q29: Annex 3 A6 Civil works (SAR 745,743) | R29: 81 | S29: =R29/1000 | T29: 46530 | U29: 46548 | V29: 15
A30: A1 | B30: A1 CCTV system | C30: NRY-P1010 | D30: Manufacture CCTV cameras and analytics - Riyadh (Thumamah) | E30: PRO.NRY.CCT | F30: Procurement | G30: NRY | H30: MS4 | I30: 0.2 | J30: =Station_BOQ!R5 | K30: =I30*62000000*J30 | L30: 0.14806936 | M30: =ROUND(K30*L30,0) | N30: 103080 | O30: =N30-M30 | P30: MS4 Material delivery 20% x station price share 5.61% | BOQ section share 19.7% of station equipment x 75% (manufacture) | Q30: Annex 3 A1 CCTV system (SAR 338,989) | R30: 255 | S30: =R30/1000 | T30: 46509 | U30: 46580 | V30: 47
A31: A2 | B31: A2 Video management and video wall | C31: NRY-P1020 | D31: Manufacture video management servers, storage and video wall - Riyadh (Thumamah) | E31: PRO.NRY.VMS | F31: Procurement | G31: NRY | H31: MS4 | I31: 0.2 | J31: =Station_BOQ!R5 | K31: =I31*62000000*J31 | L31: 0.18220591 | M31: =ROUND(K31*L31,0) | N31: 126844 | O31: =N31-M31 | P31: MS4 Material delivery 20% x station price share 5.61% | BOQ section share 24.3% of station equipment x 75% (manufacture) | Q31: Annex 3 A2 Video management and wall (SAR 417,141) | R31: 314 | S31: =R31/1000 | T31: 46509 | U31: 46580 | V31: 47
A32: A3 | B32: A3 Access control and intercom | C32: NRY-P1030 | D32: Manufacture access control and intercom equipment - Riyadh (Thumamah) | E32: PRO.NRY.ACC | F32: Procurement | G32: NRY | H32: MS4 | I32: 0.2 | J32: =Station_BOQ!R5 | K32: =I32*62000000*J32 | L32: 0.019256193 | M32: =ROUND(K32*L32,0) | N32: 13405 | O32: =N32-M32 | P32: MS4 Material delivery 20% x station price share 5.61% | BOQ section share 2.6% of station equipment x 75% (manufacture) | Q32: Annex 3 A3 Access control and intercom (SAR 44,085) | R32: 33 | S32: =R32/1000 | T32: 46509 | U32: 46580 | V32: 47
A33: A4, A5 | B33: A4 UPS and A5 Poles, cabinets and network | C33: NRY-P1040 | D33: Manufacture UPS, network switches and field cabinets - Riyadh (Thumamah) | E33: PRO.NRY.UPN | F33: Procurement | G33: NRY | H33: MS4 | I33: 0.2 | J33: =Station_BOQ!R5 | K33: =I33*62000000*J33 | L33: 0.40046854 | M33: =ROUND(K33*L33,0) | N33: 278789 | O33: =N33-M33 | P33: MS4 Material delivery 20% x station price share 5.61% | BOQ section share 53.4% of station equipment x 75% (manufacture) | Q33: Annex 3 A4 UPS + A5 poles, cabinets and network (SAR 916,830) | R33: 691 | S33: =R33/1000 | T33: 46509 | U33: 46580 | V33: 47
A34: SH-FAT | B34: Factory acceptance test (per railway, allocated) | C34: NRY-P1050 | D34: Factory acceptance test at vendor premises - Riyadh (Thumamah) | E34: PRO.NRY.LOG | F34: Procurement | G34: NRY | H34: MS4 | I34: 0.2 | J34: =Station_BOQ!R5 | K34: =I34*62000000*J34 | L34: 0.05 | M34: =ROUND(K34*L34,0) | N34: 34808 | O34: =N34-M34 | P34: MS4 Material delivery 20% x station price share 5.61% | Fixed key 5% (FAT) | Q34: Annex 3 Factory acceptance test (railway), allocated by hardware share | R34: 216 | S34: =R34/1000 | T34: 46581 | U34: 46594 | V34: 10
A35: A1-A5 | B35: A1 to A5 equipment sections: logistics (shipping, customs, delivery) share | C35: NRY-P1060 | D35: Shipping and customs clearance - Riyadh (Thumamah) | E35: PRO.NRY.LOG | F35: Procurement | G35: NRY | H35: MS4 | I35: 0.2 | J35: =Station_BOQ!R5 | K35: =I35*62000000*J35 | L35: 0.15 | M35: =ROUND(K35*L35,0) | N35: 104424 | O35: =N35-M35 | P35: MS4 Material delivery 20% x station price share 5.61% | Fixed key 15% (shipping and customs) | Q35: Annex 3 equipment sections A1-A5 (logistics share) | R35: 431 | S35: =R35/1000 | T35: 46595 | U35: 46624 | V35: 22
A36: SH-SPR | B36: Commissioning spares (per railway, allocated) | C36: NRY-P1070 | D36: Delivery to station and receiving inspection - Riyadh (Thumamah) | E36: PRO.NRY.LOG | F36: Procurement | G36: NRY | H36: MS4 | I36: 0.2 | J36: =Station_BOQ!R5 | K36: =I36*62000000*J36 | L36: 0.05 | M36: =ROUND(K36*L36,0) | N36: 34808 | O36: =N36-M36 | P36: MS4 Material delivery 20% x station price share 5.61% | Fixed key 5% (delivery, receiving) incl. commissioning spares | Q36: Annex 3 Commissioning spares (railway), allocated by hardware share | R36: 216 | S36: =R36/1000 | T36: 46625 | U36: 46631 | V36: 5
A37: A6 | B37: A6 Civil works | C37: NRY-C1010 | D37: Civil: platform trenches and duct banks - Riyadh (Thumamah) | E37: CON.NRY.CIV | F37: Construction | G37: NRY | H37: MS5 | I37: 0.2 | J37: =Station_BOQ!R5 | K37: =I37*62000000*J37 | L37: 0.15140219 | M37: =ROUND(K37*L37,0) | N37: 105400 | O37: =N37-M37 | P37: MS5 Installation 20% x station price share 5.61% | BOQ civil share 30.3% x 50% (trenches and duct banks) | Q37: Annex 3 A6 Civil works (SAR 745,743) | R37: 350 | S37: =R37/1000 | T37: 46551 | U37: 46629 | V37: 57
A38: A6 | B38: A6 Civil works | C38: NRY-C1020 | D38: Civil: camera and ALPR pole foundations and poles - Riyadh (Thumamah) | E38: CON.NRY.CIV | F38: Construction | G38: NRY | H38: MS5 | I38: 0.2 | J38: =Station_BOQ!R5 | K38: =I38*62000000*J38 | L38: 0.12112175 | M38: =ROUND(K38*L38,0) | N38: 84320 | O38: =N38-M38 | P38: MS5 Installation 20% x station price share 5.61% | BOQ civil share 30.3% x 40% (poles) | Q38: Annex 3 A6 Civil works (SAR 745,743) | R38: 269 | S38: =R38/1000 | T38: 46602 | U38: 46665 | V38: 45
A39: A1-A5 | B39: A1 to A5 equipment sections: installation share (works included in unit prices) | C39: NRY-C2010 | D39: Install UPS, network switches and field cabinets - Riyadh (Thumamah) | E39: CON.NRY.INS | F39: Construction | G39: NRY | H39: MS5 | I39: 0.2 | J39: =Station_BOQ!R5 | K39: =I39*62000000*J39 | L39: 0.13943912 | M39: =ROUND(K39*L39,0) | N39: 97072 | O39: =N39-M39 | P39: MS5 Installation 20% x station price share 5.61% | Installation key 20% x (1 - civil share 30.3%) | Q39: Annex 3 equipment sections A1-A5 (installation share) | R39: 162 | S39: =R39/1000 | T39: 46632 | U39: 46650 | V39: 13
A40: A1-A5 | B40: A1 to A5 equipment sections: installation share (works included in unit prices) | C40: NRY-C2020 | D40: Cabling and termination (power, fibre, data) - Riyadh (Thumamah) | E40: CON.NRY.INS | F40: Construction | G40: NRY | H40: MS5 | I40: 0.2 | J40: =Station_BOQ!R5 | K40: =I40*62000000*J40 | L40: 0.20915869 | M40: =ROUND(K40*L40,0) | N40: 145607 | O40: =N40-M40 | P40: MS5 Installation 20% x station price share 5.61% | Installation key 30% x (1 - civil share 30.3%) | Q40: Annex 3 equipment sections A1-A5 (installation share) | R40: 323 | S40: =R40/1000 | T40: 46638 | U40: 46670 | V40: 22
A41: A1-A5 | B41: A1 to A5 equipment sections: installation share (works included in unit prices) | C41: NRY-C2030 | D41: Install and aim CCTV cameras - Riyadh (Thumamah) | E41: CON.NRY.INS | F41: Construction | G41: NRY | H41: MS5 | I41: 0.2 | J41: =Station_BOQ!R5 | K41: =I41*62000000*J41 | L41: 0.1742989 | M41: =ROUND(K41*L41,0) | N41: 121339 | O41: =N41-M41 | P41: MS5 Installation 20% x station price share 5.61% | Installation key 25% x (1 - civil share 30.3%) | Q41: Annex 3 equipment sections A1-A5 (installation share) | R41: 269 | S41: =R41/1000 | T41: 46671 | U41: 46694 | V41: 18
...

Sheet Distribution_Keys
A1: Distribution keys (cost within each payment milestone, and progress weights)
A3: Milestone | B3: Activity template | C3: Key | D3: Basis
A4: MS2 | B4: Survey, concept, preliminary, detailed, IFC, HCIS submittals | C4: 5 / 10 / 20 / 40 / 20 / 5 % of 98% | D4: Survey (including the permit follow-up) carries 7% of the MS2 bucket; design effort split by stage; the railway design and engineering package sits inside the station price
A5: MS3 | B5: Approval activities of the same six stages | C5: 5 / 10 / 20 / 40 / 20 / 5 % | D5: Mirror of the submittal key. Every SAR review is 21 days (15 working days)
A6: MS4 | B6: Manufacture CCTV, VMS, access control, UPS and network | C6: 75% split by BOQ section share | D6: A1, A2, A3 and A4+A5 shares of the station equipment value
A7: MS4 | B7: FAT / shipping and customs / delivery and receiving | C7: 5 / 15 / 5 % | D7: Fixed keys; spares and logistics sit inside delivery
A8: MS5 | B8: Enabling works / civil trenches and duct banks / poles and foundations | C8: 4 + 6 / 50 / 40 % of the A6 share | D8: A6 civil works share of station hardware; enabling works carved from the civil line
A9: MS5 | B9: Install cabinets / cabling / CCTV / VMS / access control | C9: 20 / 30 / 25 / 15 / 10 % of (1 - A6 share) | D9: Installation is included in the unit prices (Annex 3 works included)
A10: MS6 | B10: Pre-commissioning / SAT | C10: 40 / 60 % | D10: Fixed keys. Riyadh (Thumamah): 97% of the keys, 3% to the mock-up approval (no separate Annex 3 item)
A11: MS7 | B11: As-built submittal / approval / training / trial operation / handover | C11: 15 / 5 / 15 / 35 / 30 % | D11: Fixed keys
A12: MS1 | B12: Performance security / initial baseline / site establishment / mobilization submittals | C12: 15 / 10 / 45 / 30 % | D12: Project level, 20% of the total price
A15: EPC phase | B15: Component | C15: Weight (% of station progress) | D15: Basis
A16: Engineering | B16: Survey 8, concept 10, preliminary 18, detailed 30, IFC 18, HCIS 6, as-built 10 (of 12%); each stage split submittal / approval by duration | C16: 12 | D16: Typical EPC effort weighting for design
A17: Procurement | B17: Manufacture 24 (split by BOQ package share), FAT 4, shipping 8, delivery 4 | C17: 40 | D17: Procurement carries the largest share of a supply-led security contract
A18: Construction | B18: Enabling works 2.5, trenches 6.5, poles 5, cabinets 3, cabling 6, CCTV 5, VMS 3, access 2 | C18: 33 | D18: Site works
A19: Commissioning and handover | B19: Pre-commissioning 3, SAT 4, training 2, trial operation 3, handover 3 | C19: 15 | D19: Testing, trial and acceptance
A20: Total stations | C20: =SUM(C16:C19) | D20: Station weights sum to 100%
A22: Project level | B22: Mobilization and baseline 2.7% and closeout pack 1.3% of the whole project | C22: 4 | D22: Stations carry 96% of the project, each station weighted by its BOQ price share

Sheet S_Curve
A1: S-curve: cost (contract payment conditions) against progress (fair EPC distribution), spread linearly over each activity
A3: Month | B3: Cost in month (SAR) | C3: Cumulative cost (SAR) | D3: Cumulative cost % | E3: Progress in month % | F3: Cumulative progress %
A4: 46327 | B4: 10056396 | C4: =SUM(B$4:B4) | D4: =C4/62000000 | E4: 0.018348889 | F4: =SUM(E$4:E4)
A5: 46357 | B5: 2343599.5 | C5: =SUM(B$4:B5) | D5: =C5/62000000 | E5: 0.0036511111 | F5: =SUM(E$4:E5)
A6: 46388 | B6: 262431.14 | C6: =SUM(B$4:B6) | D6: =C6/62000000 | E6: 0.0070103619 | F6: =SUM(E$4:E6)
A7: 46419 | B7: 728474.66 | C7: =SUM(B$4:B7) | D7: =C7/62000000 | E7: 0.0074628639 | F7: =SUM(E$4:E7)
A8: 46447 | B8: 1149269 | C8: =SUM(B$4:B8) | D8: =C8/62000000 | E8: 0.0098651858 | F8: =SUM(E$4:E8)
A9: 46478 | B9: 1744434.9 | C9: =SUM(B$4:B9) | D9: =C9/62000000 | E9: 0.013752755 | F9: =SUM(E$4:E9)
A10: 46508 | B10: 1442176.6 | C10: =SUM(B$4:B10) | D10: =C10/62000000 | E10: 0.027052797 | F10: =SUM(E$4:E10)
A11: 46539 | B11: 1684819.1 | C11: =SUM(B$4:B11) | D11: =C11/62000000 | E11: 0.036512083 | F11: =SUM(E$4:E11)
A12: 46569 | B12: 1309023.7 | C12: =SUM(B$4:B12) | D12: =C12/62000000 | E12: 0.042003483 | F12: =SUM(E$4:E12)
A13: 46600 | B13: 1682555.5 | C13: =SUM(B$4:B13) | D13: =C13/62000000 | E13: 0.052617629 | F13: =SUM(E$4:E13)
A14: 46631 | B14: 1807538.7 | C14: =SUM(B$4:B14) | D14: =C14/62000000 | E14: 0.04574256 | F14: =SUM(E$4:E14)
A15: 46661 | B15: 1709705 | C15: =SUM(B$4:B15) | D15: =C15/62000000 | E15: 0.038601208 | F15: =SUM(E$4:E15)
... A38: 47362 | B38: 41713.773 | C38: =SUM(B$4:B38) | D38: =C38/62000000 | E38: 0.013656364 | F38: =SUM(E$4:E38)

Sheet Resources
A1: Resource ID | B1: Name | C1: Type | D1: Unit | E1: Price per unit | F1: Meaning | G1: How P6 uses it
A2: COST-SAR | B2: Contract cost (BOQ x payment milestones) | C2: Material | D2: SAR | E2: 0 | F2: Contract cost of the activity in SAR from the payment conditions applied to the BOQ station value (column N of BOQ_Mapping) | G2: Quantity carrier. Price 0, so it adds no budget cost. Set the price to 1 (and PROG-WT to 0) to see the contract-condition cost curve instead.
A3: PROG-WT | B3: Progress weight (fair EPC distribution, SAR value) | C3: Material | D3: SAR | E3: 1 | F3: Progress share x SAR 62,000,000 (100,000 points x SAR 620). Fair EPC distribution (see Distribution_Keys) | G3: Price 1, so budgeted cost = progress value in SAR. Activity % complete type is Physical, so earned value = physical % x this budget, and the cost and schedule performance indexes are measured in SAR on the progress distribution.

Sheet Activity_Codes
A1: Code type | B1: Code value | C1: Description | D1: Activities
A2: Area | B2: EWR | C2: EWR | D2: 164
A3: Area | B3: HHR | C3: HHR | D3: 164
A4: Area | B4: NSR | C4: NSR | D4: 248
A5: Area | B5: PRJ | C5: Project level | D5: 15
A6: Discipline | B6: ACC | C6: Access control and intercom | D6: 28
A7: Discipline | B7: CCTV | C7: CCTV system | D7: 42
A8: Discipline | B8: CIVIL | C8: Civil works | D8: 56
A9: Discipline | B9: DOCS | C9: Design documentation | D9: 224
A10: Discipline | B10: PM | C10: Project management and logistics | D10: 85
A11: Discipline | B11: TC | C11: Testing, commissioning and handover | D11: 100
A12: Discipline | B12: UPSNET | C12: UPS, network and cabinets | D12: 28
A13: Discipline | B13: VMS | C13: Video management and wall | D13: 28
... A73: Submittal or approval | B73: Submittal | C73: Submittal | D73: 101

Sheet WBS
A1: WBS code | B1: Name | C1: Level | D1: Parent
A2: 0580 | B2: 0580-Security Technology Salutation after eliminating Passenger Checking Roles | C2: 1
A3: PM | B3: Project Management and Mobilization | C3: 2 | D3: 0580
A4: ENG | B4: Engineering | C4: 2 | D4: 0580
A5: PRO | B5: Procurement | C5: 2 | D5: 0580
A6: CON | B6: Construction | C6: 2 | D6: 0580
A7: COM | B7: Commissioning and Handover | C7: 2 | D7: 0580
A8: PM.MOB | B8: Mobilization and baseline programme | C8: 3 | D8: PM
A9: PM.MST | B9: Contract milestones | C9: 3 | D9: PM
A10: PM.CLO | B10: Closeout | C10: 3 | D10: PM
A11: ENG.NRY | B11: Riyadh (Thumamah) (NSR) | C11: 3 | D11: ENG
A12: PRO.NRY | B12: Riyadh (Thumamah) (NSR) | C12: 3 | D12: PRO
A13: CON.NRY | B13: Riyadh (Thumamah) (NSR) | C13: 3 | D13: CON
A14: COM.NRY | B14: Riyadh (Thumamah) (NSR) | C14: 3 | D14: COM
... A515: COM.NQR.TOA | B515: Trial operation and acceptance | C515: 4 | D515: COM.NQR

Sheet Relationships
A1: Predecessor | B1: Successor | C1: Type | D1: Lag (work days)
A2: PRJ-M0000 | B2: PRJ-A1010 | C2: FS | D2: 0
A3: PRJ-M0000 | B3: PRJ-A1020 | C3: FS | D3: 0
A4: PRJ-A1020 | B4: PRJ-A1030 | C4: FS | D4: 0
A5: PRJ-M0000 | B5: PRJ-A1040 | C5: FS | D5: 5
A6: PRJ-M0000 | B6: PRJ-A1050 | C6: FS | D6: 5
A7: PRJ-M0000 | B7: PRJ-A1060 | C7: FS | D7: 0
A8: PRJ-A1010 | B8: PRJ-M1100 | C8: FS | D8: 0
A9: PRJ-A1030 | B9: PRJ-M1100 | C9: FS | D9: 0
A10: PRJ-A1040 | B10: PRJ-M1100 | C10: FS | D10: 0
A11: PRJ-A1050 | B11: PRJ-M1100 | C11: FS | D11: 0
A12: PRJ-M1100 | B12: PRJ-M1150 | C12: FS | D12: 0
A13: PRJ-M0000 | B13: PRJ-M1150 | C13: FS | D13: 45
... A913: PRJ-M0000 | B913: PRJ-MX99 | C913: FS | D913: 750

Sheet Invoicing_Monthly
A1: Invoices per month, detailed: each payment milestone is invoiced in the month its milestone activity is achieved in the programme
A2: Amount = clause 15 payment milestone x Annex 3 station price (formulas link to Payment_Milestones). Invoice month = month of the trigger milestone date. Payment terms after invoicing (days to pay) are not modelled.
A4: Invoice month | B4: Milestone date | C4: Milestone | D4: Description | E4: Station | F4: Railway | G4: Trigger activity ID | H4: Trigger activity | I4: Invoice amount (SAR) | J4: Cumulative (SAR) | K4: Cumulative %
A5: 46357 | B5: 46369 | C5: MS1 | D5: Mobilization | E5: All stations | F5: Project | G5: PRJ-M1100 | H5: MS1 Mobilization complete (payment milestone 20%) | I5: =Payment_Milestones!D5 | J5: =SUM(I$5:I5) | K5: =J5/62000000
A6: 46478 | B6: 46488 | C6: MS2 | D6: Engineering submittal | E6: Riyadh (Thumamah) (NRY) | F6: NSR | G6: NRY-E1200 | H6: MS2 Engineering submittal complete (10%) - Riyadh (Thumamah) | I6: =Payment_Milestones!C16 | J6: =SUM(I$5:I6) | K6: =J6/62000000
A7: 46478 | B7: 46488 | C7: MS2 | D7: Engineering submittal | E7: Makkah (HMK) | F7: HHR | G7: HMK-E1200 | H7: MS2 Engineering submittal complete (10%) - Makkah | I7: =Payment_Milestones!C17 | J7: =SUM(I$5:I7) | K7: =J7/62000000
A8: 46478 | B8: 46488 | C8: MS2 | D8: Engineering submittal | E8: Riyadh (Malaz) (ERY) | F8: EWR | G8: ERY-E1200 | H8: MS2 Engineering submittal complete (10%) - Riyadh (Malaz) | I8: =Payment_Milestones!C18 | J8: =SUM(I$5:I8) | K8: =J8/62000000
A9: 46508 | B9: 46509 | C9: MS3 | D9: SAR approval of engineering | E9: Riyadh (Thumamah) (NRY) | F9: NSR | G9: NRY-E1210 | H9: MS3 Engineering approved by SAR (10%) - Riyadh (Thumamah) | I9: =Payment_Milestones!D16 | J9: =SUM(I$5:I9) | K9: =J9/62000000
A10: 46508 | B10: 46509 | C10: MS3 | D10: SAR approval of engineering | E10: Makkah (HMK) | F10: HHR | G10: HMK-E1210 | H10: MS3 Engineering approved by SAR (10%) - Makkah | I10: =Payment_Milestones!D17 | J10: =SUM(I$5:I10) | K10: =J10/62000000
A11: 46508 | B11: 46509 | C11: MS3 | D11: SAR approval of engineering | E11: Riyadh (Malaz) (ERY) | F11: EWR | G11: ERY-E1210 | H11: MS3 Engineering approved by SAR (10%) - Riyadh (Malaz) | I11: =Payment_Milestones!D18 | J11: =SUM(I$5:I11) | K11: =J11/62000000
A12: 46539 | B12: 46544 | C12: MS2 | D12: Engineering submittal | E12: Jeddah (HJD) | F12: HHR | G12: HJD-E1200 | H12: MS2 Engineering submittal complete (10%) - Jeddah | I12: =Payment_Milestones!C19 | J12: =SUM(I$5:I12) | K12: =J12/62000000
A13: 46539 | B13: 46565 | C13: MS3 | D13: SAR approval of engineering | E13: Jeddah (HJD) | F13: HHR | G13: HJD-E1210 | H13: MS3 Engineering approved by SAR (10%) - Jeddah | I13: =Payment_Milestones!D19 | J13: =SUM(I$5:I13) | K13: =J13/62000000
A14: 46600 | B14: 46624 | C14: MS4 | D14: Material delivery | E14: Riyadh (Malaz) (ERY) | F14: EWR | G14: ERY-P1100 | H14: MS4 Material delivered (20%) - Riyadh (Malaz) | I14: =Payment_Milestones!E18 | J14: =SUM(I$5:I14) | K14: =J14/62000000
A15: 46631 | B15: 46632 | C15: MS4 | D15: Material delivery | E15: Riyadh (Thumamah) (NRY) | F15: NSR | G15: NRY-P1100 | H15: MS4 Material delivered (20%) - Riyadh (Thumamah) | I15: =Payment_Milestones!E16 | J15: =SUM(I$5:I15) | K15: =J15/62000000
A16: 46631 | B16: 46651 | C16: MS2 | D16: Engineering submittal | E16: Dammam (EDM) | F16: EWR | G16: EDM-E1200 | H16: MS2 Engineering submittal complete (10%) - Dammam | I16: =Payment_Milestones!C20 | J16: =SUM(I$5:I16) | K16: =J16/62000000
A17: 46661 | B17: 46673 | C17: MS3 | D17: SAR approval of engineering | E17: Dammam (EDM) | F17: EWR | G17: EDM-E1210 | H17: MS3 Engineering approved by SAR (10%) - Dammam | I17: =Payment_Milestones!D20 | J17: =SUM(I$5:I17) | K17: =J17/62000000
A18: 46661 | B18: 46679 | C18: MS5 | D18: Installation | E18: Riyadh (Malaz) (ERY) | F18: EWR | G18: ERY-C2100 | H18: MS5 Installation complete (20%) - Riyadh (Malaz) | I18: =Payment_Milestones!F18 | J18: =SUM(I$5:I18) | K18: =J18/62000000
A19: 46692 | B19: 46695 | C19: MS5 | D19: Installation | E19: Riyadh (Thumamah) (NRY) | F19: NSR | G19: NRY-C2100 | H19: MS5 Installation complete (20%) - Riyadh (Thumamah) | I19: =Payment_Milestones!F16 | J19: =SUM(I$5:I19) | K19: =J19/62000000
A20: 46692 | B20: 46695 | C20: MS6 | D20: Testing and commissioning (SAT) | E20: Riyadh (Malaz) (ERY) | F20: EWR | G20: ERY-T1100 | H20: MS6 SAT complete (10%) - Riyadh (Malaz) | I20: =Payment_Milestones!G18 | J20: =SUM(I$5:I20) | K20: =J20/62000000
A21: 46692 | B21: 46700 | C21: MS4 | D21: Material delivery | E21: Makkah (HMK) | F21: HHR | G21: HMK-P1100 | H21: MS4 Material delivered (20%) - Makkah | I21: =Payment_Milestones!E17 | J21: =SUM(I$5:I21) | K21: =J21/62000000
A22: 46692 | B22: 46705 | C22: MS2 | D22: Engineering submittal | E22: Al Qassim (NQS) | F22: NSR | G22: NQS-E1200 | H22: MS2 Engineering submittal complete (10%) - Al Qassim | I22: =Payment_Milestones!C21 | J22: =SUM(I$5:I22) | K22: =J22/62000000
A23: 46692 | B23: 46705 | C23: MS2 | D23: Engineering submittal | E23: Hufuf (EHF) | F23: EWR | G23: EHF-E1200 | H23: MS2 Engineering submittal complete (10%) - Hufuf | I23: =Payment_Milestones!C22 | J23: =SUM(I$5:I23) | K23: =J23/62000000
A24: 46722 | B24: 46726 | C24: MS3 | D24: SAR approval of engineering | E24: Al Qassim (NQS) | F24: NSR | G24: NQS-E1210 | H24: MS3 Engineering approved by SAR (10%) - Al Qassim | I24: =Payment_Milestones!D21 | J24: =SUM(I$5:I24) | K24: =J24/62000000
A25: 46722 | B25: 46726 | C25: MS3 | D25: SAR approval of engineering | E25: Hufuf (EHF) | F25: EWR | G25: EHF-E1210 | H25: MS3 Engineering approved by SAR (10%) - Hufuf | I25: =Payment_Milestones!D22 | J25: =SUM(I$5:I25) | K25: =J25/62000000
A26: 46722 | B26: 46727 | C26: MS6 | D26: Testing and commissioning (SAT) | E26: Riyadh (Thumamah) (NRY) | F26: NSR | G26: NRY-T1100 | H26: MS6 SAT complete (10%) - Riyadh (Thumamah) | I26: =Payment_Milestones!G16 | J26: =SUM(I$5:I26) | K26: =J26/62000000
A27: 46722 | B27: 46748 | C27: MS4 | D27: Material delivery | E27: Jeddah (HJD) | F27: HHR | G27: HJD-P1100 | H27: MS4 Material delivered (20%) - Jeddah | I27: =Payment_Milestones!E19 | J27: =SUM(I$5:I27) | K27: =J27/62000000
A28: 46722 | B28: 46751 | C28: MS2 | D28: Engineering submittal | E28: Al Majma'ah (NMJ) | F28: NSR | G28: NMJ-E1200 | H28: MS2 Engineering submittal complete (10%) - Al Majma'ah | I28: =Payment_Milestones!C23 | J28: =SUM(I$5:I28) | K28: =J28/62000000
A29: 46753 | B29: 46769 | C29: MS7 | D29: Final acceptance and handover | E29: Riyadh (Malaz) (ERY) | F29: EWR | G29: ERY-T3100 | H29: MS7 Station accepted - final acceptance and handover (10%) - Riyadh (Malaz) | I29: =Payment_Milestones!H18 | J29: =SUM(I$5:I29) | K29: =J29/62000000
A30: 46753 | B30: 46772 | C30: MS3 | D30: SAR approval of engineering | E30: Al Majma'ah (NMJ) | F30: NSR | G30: NMJ-E1210 | H30: MS3 Engineering approved by SAR (10%) - Al Majma'ah | I30: =Payment_Milestones!D23 | J30: =SUM(I$5:I30) | K30: =J30/62000000
A31: 46753 | B31: 46783 | C31: MS4 | D31: Material delivery | E31: Dammam (EDM) | F31: EWR | G31: EDM-P1100 | H31: MS4 Material delivered (20%) - Dammam | I31: =Payment_Milestones!E20 | J31: =SUM(I$5:I31) | K31: =J31/62000000
A32: 46784 | B32: 46786 | C32: MS7 | D32: Final acceptance and handover | E32: Riyadh (Thumamah) (NRY) | F32: NSR | G32: NRY-T3100 | H32: MS7 Station accepted - final acceptance and handover (10%) - Riyadh (Thumamah) | I32: =Payment_Milestones!H16 | J32: =SUM(I$5:I32) | K32: =J32/62000000
A33: 46813 | B33: 46820 | C33: MS5 | D33: Installation | E33: Makkah (HMK) | F33: HHR | G33: HMK-C2100 | H33: MS5 Installation complete (20%) - Makkah | I33: =Payment_Milestones!F17 | J33: =SUM(I$5:I33) | K33: =J33/62000000
A34: 46813 | B34: 46839 | C34: MS4 | D34: Material delivery | E34: Hufuf (EHF) | F34: EWR | G34: EHF-P1100 | H34: MS4 Material delivered (20%) - Hufuf | I34: =Payment_Milestones!E22 | J34: =SUM(I$5:I34) | K34: =J34/62000000
A35: 46813 | B35: 46842 | C35: MS5 | D35: Installation | E35: Dammam (EDM) | F35: EWR | G35: EDM-C2100 | H35: MS5 Installation complete (20%) - Dammam | I35: =Payment_Milestones!F20 | J35: =SUM(I$5:I35) | K35: =J35/62000000
A36: 46844 | B36: 46849 | C36: MS4 | D36: Material delivery | E36: Al Qassim (NQS) | F36: NSR | G36: NQS-P1100 | H36: MS4 Material delivered (20%) - Al Qassim | I36: =Payment_Milestones!E21 | J36: =SUM(I$5:I36) | K36: =J36/62000000
A37: 46844 | B37: 46849 | C37: MS5 | D37: Installation | E37: Jeddah (HJD) | F37: HHR | G37: HJD-C2100 | H37: MS5 Installation complete (20%) - Jeddah | I37: =Payment_Milestones!F19 | J37: =SUM(I$5:I37) | K37: =J37/62000000
A38: 46844 | B38: 46860 | C38: MS6 | D38: Testing and commissioning (SAT) | E38: Dammam (EDM) | F38: EWR | G38: EDM-T1100 | H38: MS6 SAT complete (10%) - Dammam | I38: =Payment_Milestones!G20 | J38: =SUM(I$5:I38) | K38: =J38/62000000
A39: 46844 | B39: 46861 | C39: MS2 | D39: Engineering submittal | E39: KAEC (HKA) | F39: HHR | G39: HKA-E1200 | H39: MS2 Engineering submittal complete (10%) - KAEC | I39: =Payment_Milestones!C24 | J39: =SUM(I$5:I39) | K39: =J39/62000000
A40: 46844 | B40: 46861 | C40: MS2 | D40: Engineering submittal | E40: Madinah (HMD) | F40: HHR | G40: HMD-E1200 | H40: MS2 Engineering submittal complete (10%) - Madinah | I40: =Payment_Milestones!C25 | J40: =SUM(I$5:I40) | K40: =J40/62000000
A41: 46844 | B41: 46862 | C41: MS6 | D41: Testing and commissioning (SAT) | E41: Makkah (HMK) | F41: HHR | G41: HMK-T1100 | H41: MS6 SAT complete (10%) - Makkah | I41: =Payment_Milestones!G17 | J41: =SUM(I$5:I41) | K41: =J41/62000000
...
